ERROR 2025-09-04 18:08:17 huggingface_utils generate_quiz_from_huggingface Error connecting to Hugging Face API: HTTPSConnectionPool(host='api-inference.huggingface.co', port=443): Max retries exceeded with url: /models/google/flan-t5-large (Caused by ProxyError('Unable to connect to proxy', NewConnectionError('<urllib3.connection.HTTPSConnection object at 0x000001CBB19F02F0>: Failed to establish a new connection: [WinError 10061] No connection could be made because the target machine actively refused it')))
Traceback (most recent call last):
  File "D:\Design & Source Code\Source Coding\Talented\venv\Lib\site-packages\urllib3\connection.py", line 198, in _new_conn
    sock = connection.create_connection(
        (self._dns_host, self.port),
    ...<2 lines>...
        socket_options=self.socket_options,
    )
  File "D:\Design & Source Code\Source Coding\Talented\venv\Lib\site-packages\urllib3\util\connection.py", line 85, in create_connection
    raise err
  File "D:\Design & Source Code\Source Coding\Talented\venv\Lib\site-packages\urllib3\util\connection.py", line 73, in create_connection
    sock.connect(sa)
    ~~~~~~~~~~~~^^^^
ConnectionRefusedError: [WinError 10061] No connection could be made because the target machine actively refused it

The above exception was the direct cause of the following exception:

Traceback (most recent call last):
  File "D:\Design & Source Code\Source Coding\Talented\venv\Lib\site-packages\urllib3\connectionpool.py", line 773, in urlopen
    self._prepare_proxy(conn)
    ~~~~~~~~~~~~~~~~~~~^^^^^^
  File "D:\Design & Source Code\Source Coding\Talented\venv\Lib\site-packages\urllib3\connectionpool.py", line 1042, in _prepare_proxy
    conn.connect()
    ~~~~~~~~~~~~^^
  File "D:\Design & Source Code\Source Coding\Talented\venv\Lib\site-packages\urllib3\connection.py", line 753, in connect
    self.sock = sock = self._new_conn()
                       ~~~~~~~~~~~~~~^^
  File "D:\Design & Source Code\Source Coding\Talented\venv\Lib\site-packages\urllib3\connection.py", line 213, in _new_conn
    raise NewConnectionError(
        self, f"Failed to establish a new connection: {e}"
    ) from e
urllib3.exceptions.NewConnectionError: <urllib3.connection.HTTPSConnection object at 0x000001CBB19F02F0>: Failed to establish a new connection: [WinError 10061] No connection could be made because the target machine actively refused it

The above exception was the direct cause of the following exception:

urllib3.exceptions.ProxyError: ('Unable to connect to proxy', NewConnectionError('<urllib3.connection.HTTPSConnection object at 0x000001CBB19F02F0>: Failed to establish a new connection: [WinError 10061] No connection could be made because the target machine actively refused it'))

The above exception was the direct cause of the following exception:

Traceback (most recent call last):
  File "D:\Design & Source Code\Source Coding\Talented\venv\Lib\site-packages\requests\adapters.py", line 644, in send
    resp = conn.urlopen(
        method=request.method,
    ...<9 lines>...
        chunked=chunked,
    )
  File "D:\Design & Source Code\Source Coding\Talented\venv\Lib\site-packages\urllib3\connectionpool.py", line 841, in urlopen
    retries = retries.increment(
        method, url, error=new_e, _pool=self, _stacktrace=sys.exc_info()[2]
    )
  File "D:\Design & Source Code\Source Coding\Talented\venv\Lib\site-packages\urllib3\util\retry.py", line 519, in increment
    raise MaxRetryError(_pool, url, reason) from reason  # type: ignore[arg-type]
    ^^^^^^^^^^^^^^^^^^^^^^^^^^^^^^^^^^^^^^^^^^^^^^^^^^^
urllib3.exceptions.MaxRetryError: HTTPSConnectionPool(host='api-inference.huggingface.co', port=443): Max retries exceeded with url: /models/google/flan-t5-large (Caused by ProxyError('Unable to connect to proxy', NewConnectionError('<urllib3.connection.HTTPSConnection object at 0x000001CBB19F02F0>: Failed to establish a new connection: [WinError 10061] No connection could be made because the target machine actively refused it')))

During handling of the above exception, another exception occurred:

Traceback (most recent call last):
  File "D:\Design & Source Code\Source Coding\Talented\quiz_finder\huggingface_utils.py", line 74, in generate_quiz_from_huggingface
    response = requests.post(API_URL, headers=headers, json=payload, timeout=45)
  File "D:\Design & Source Code\Source Coding\Talented\venv\Lib\site-packages\requests\api.py", line 115, in post
    return request("post", url, data=data, json=json, **kwargs)
  File "D:\Design & Source Code\Source Coding\Talented\venv\Lib\site-packages\requests\api.py", line 59, in request
    return session.request(method=method, url=url, **kwargs)
           ~~~~~~~~~~~~~~~^^^^^^^^^^^^^^^^^^^^^^^^^^^^^^^^^^
  File "D:\Design & Source Code\Source Coding\Talented\venv\Lib\site-packages\requests\sessions.py", line 589, in request
    resp = self.send(prep, **send_kwargs)
  File "D:\Design & Source Code\Source Coding\Talented\venv\Lib\site-packages\requests\sessions.py", line 703, in send
    r = adapter.send(request, **kwargs)
  File "D:\Design & Source Code\Source Coding\Talented\venv\Lib\site-packages\requests\adapters.py", line 671, in send
    raise ProxyError(e, request=request)
requests.exceptions.ProxyError: HTTPSConnectionPool(host='api-inference.huggingface.co', port=443): Max retries exceeded with url: /models/google/flan-t5-large (Caused by ProxyError('Unable to connect to proxy', NewConnectionError('<urllib3.connection.HTTPSConnection object at 0x000001CBB19F02F0>: Failed to establish a new connection: [WinError 10061] No connection could be made because the target machine actively refused it')))
ERROR 2025-09-04 18:15:09 huggingface_utils generate_quiz_from_huggingface Error connecting to Hugging Face API: HTTPSConnectionPool(host='api-inference.huggingface.co', port=443): Max retries exceeded with url: /models/google/flan-t5-large (Caused by ProxyError('Unable to connect to proxy', NewConnectionError('<urllib3.connection.HTTPSConnection object at 0x000002543280C050>: Failed to establish a new connection: [WinError 10061] No connection could be made because the target machine actively refused it')))
Traceback (most recent call last):
  File "D:\Design & Source Code\Source Coding\Talented\venv\Lib\site-packages\urllib3\connection.py", line 198, in _new_conn
    sock = connection.create_connection(
        (self._dns_host, self.port),
    ...<2 lines>...
        socket_options=self.socket_options,
    )
  File "D:\Design & Source Code\Source Coding\Talented\venv\Lib\site-packages\urllib3\util\connection.py", line 85, in create_connection
    raise err
  File "D:\Design & Source Code\Source Coding\Talented\venv\Lib\site-packages\urllib3\util\connection.py", line 73, in create_connection
    sock.connect(sa)
    ~~~~~~~~~~~~^^^^
ConnectionRefusedError: [WinError 10061] No connection could be made because the target machine actively refused it

The above exception was the direct cause of the following exception:

Traceback (most recent call last):
  File "D:\Design & Source Code\Source Coding\Talented\venv\Lib\site-packages\urllib3\connectionpool.py", line 773, in urlopen
    self._prepare_proxy(conn)
    ~~~~~~~~~~~~~~~~~~~^^^^^^
  File "D:\Design & Source Code\Source Coding\Talented\venv\Lib\site-packages\urllib3\connectionpool.py", line 1042, in _prepare_proxy
    conn.connect()
    ~~~~~~~~~~~~^^
  File "D:\Design & Source Code\Source Coding\Talented\venv\Lib\site-packages\urllib3\connection.py", line 753, in connect
    self.sock = sock = self._new_conn()
                       ~~~~~~~~~~~~~~^^
  File "D:\Design & Source Code\Source Coding\Talented\venv\Lib\site-packages\urllib3\connection.py", line 213, in _new_conn
    raise NewConnectionError(
        self, f"Failed to establish a new connection: {e}"
    ) from e
urllib3.exceptions.NewConnectionError: <urllib3.connection.HTTPSConnection object at 0x000002543280C050>: Failed to establish a new connection: [WinError 10061] No connection could be made because the target machine actively refused it

The above exception was the direct cause of the following exception:

urllib3.exceptions.ProxyError: ('Unable to connect to proxy', NewConnectionError('<urllib3.connection.HTTPSConnection object at 0x000002543280C050>: Failed to establish a new connection: [WinError 10061] No connection could be made because the target machine actively refused it'))

The above exception was the direct cause of the following exception:

Traceback (most recent call last):
  File "D:\Design & Source Code\Source Coding\Talented\venv\Lib\site-packages\requests\adapters.py", line 644, in send
    resp = conn.urlopen(
        method=request.method,
    ...<9 lines>...
        chunked=chunked,
    )
  File "D:\Design & Source Code\Source Coding\Talented\venv\Lib\site-packages\urllib3\connectionpool.py", line 841, in urlopen
    retries = retries.increment(
        method, url, error=new_e, _pool=self, _stacktrace=sys.exc_info()[2]
    )
  File "D:\Design & Source Code\Source Coding\Talented\venv\Lib\site-packages\urllib3\util\retry.py", line 519, in increment
    raise MaxRetryError(_pool, url, reason) from reason  # type: ignore[arg-type]
    ^^^^^^^^^^^^^^^^^^^^^^^^^^^^^^^^^^^^^^^^^^^^^^^^^^^
urllib3.exceptions.MaxRetryError: HTTPSConnectionPool(host='api-inference.huggingface.co', port=443): Max retries exceeded with url: /models/google/flan-t5-large (Caused by ProxyError('Unable to connect to proxy', NewConnectionError('<urllib3.connection.HTTPSConnection object at 0x000002543280C050>: Failed to establish a new connection: [WinError 10061] No connection could be made because the target machine actively refused it')))

During handling of the above exception, another exception occurred:

Traceback (most recent call last):
  File "D:\Design & Source Code\Source Coding\Talented\quiz_finder\huggingface_utils.py", line 73, in generate_quiz_from_huggingface
    response = requests.post(API_URL, headers=headers, json=payload, timeout=45)
  File "D:\Design & Source Code\Source Coding\Talented\venv\Lib\site-packages\requests\api.py", line 115, in post
    return request("post", url, data=data, json=json, **kwargs)
  File "D:\Design & Source Code\Source Coding\Talented\venv\Lib\site-packages\requests\api.py", line 59, in request
    return session.request(method=method, url=url, **kwargs)
           ~~~~~~~~~~~~~~~^^^^^^^^^^^^^^^^^^^^^^^^^^^^^^^^^^
  File "D:\Design & Source Code\Source Coding\Talented\venv\Lib\site-packages\requests\sessions.py", line 589, in request
    resp = self.send(prep, **send_kwargs)
  File "D:\Design & Source Code\Source Coding\Talented\venv\Lib\site-packages\requests\sessions.py", line 703, in send
    r = adapter.send(request, **kwargs)
  File "D:\Design & Source Code\Source Coding\Talented\venv\Lib\site-packages\requests\adapters.py", line 671, in send
    raise ProxyError(e, request=request)
requests.exceptions.ProxyError: HTTPSConnectionPool(host='api-inference.huggingface.co', port=443): Max retries exceeded with url: /models/google/flan-t5-large (Caused by ProxyError('Unable to connect to proxy', NewConnectionError('<urllib3.connection.HTTPSConnection object at 0x000002543280C050>: Failed to establish a new connection: [WinError 10061] No connection could be made because the target machine actively refused it')))
ERROR 2025-09-04 18:16:15 huggingface_utils generate_quiz_from_huggingface Error connecting to Hugging Face API: HTTPSConnectionPool(host='api-inference.huggingface.co', port=443): Max retries exceeded with url: /models/google/flan-t5-large (Caused by ProxyError('Unable to connect to proxy', NewConnectionError('<urllib3.connection.HTTPSConnection object at 0x00000254329A0CD0>: Failed to establish a new connection: [WinError 10061] No connection could be made because the target machine actively refused it')))
Traceback (most recent call last):
  File "D:\Design & Source Code\Source Coding\Talented\venv\Lib\site-packages\urllib3\connection.py", line 198, in _new_conn
    sock = connection.create_connection(
        (self._dns_host, self.port),
    ...<2 lines>...
        socket_options=self.socket_options,
    )
  File "D:\Design & Source Code\Source Coding\Talented\venv\Lib\site-packages\urllib3\util\connection.py", line 85, in create_connection
    raise err
  File "D:\Design & Source Code\Source Coding\Talented\venv\Lib\site-packages\urllib3\util\connection.py", line 73, in create_connection
    sock.connect(sa)
    ~~~~~~~~~~~~^^^^
ConnectionRefusedError: [WinError 10061] No connection could be made because the target machine actively refused it

The above exception was the direct cause of the following exception:

Traceback (most recent call last):
  File "D:\Design & Source Code\Source Coding\Talented\venv\Lib\site-packages\urllib3\connectionpool.py", line 773, in urlopen
    self._prepare_proxy(conn)
    ~~~~~~~~~~~~~~~~~~~^^^^^^
  File "D:\Design & Source Code\Source Coding\Talented\venv\Lib\site-packages\urllib3\connectionpool.py", line 1042, in _prepare_proxy
    conn.connect()
    ~~~~~~~~~~~~^^
  File "D:\Design & Source Code\Source Coding\Talented\venv\Lib\site-packages\urllib3\connection.py", line 753, in connect
    self.sock = sock = self._new_conn()
                       ~~~~~~~~~~~~~~^^
  File "D:\Design & Source Code\Source Coding\Talented\venv\Lib\site-packages\urllib3\connection.py", line 213, in _new_conn
    raise NewConnectionError(
        self, f"Failed to establish a new connection: {e}"
    ) from e
urllib3.exceptions.NewConnectionError: <urllib3.connection.HTTPSConnection object at 0x00000254329A0CD0>: Failed to establish a new connection: [WinError 10061] No connection could be made because the target machine actively refused it

The above exception was the direct cause of the following exception:

urllib3.exceptions.ProxyError: ('Unable to connect to proxy', NewConnectionError('<urllib3.connection.HTTPSConnection object at 0x00000254329A0CD0>: Failed to establish a new connection: [WinError 10061] No connection could be made because the target machine actively refused it'))

The above exception was the direct cause of the following exception:

Traceback (most recent call last):
  File "D:\Design & Source Code\Source Coding\Talented\venv\Lib\site-packages\requests\adapters.py", line 644, in send
    resp = conn.urlopen(
        method=request.method,
    ...<9 lines>...
        chunked=chunked,
    )
  File "D:\Design & Source Code\Source Coding\Talented\venv\Lib\site-packages\urllib3\connectionpool.py", line 841, in urlopen
    retries = retries.increment(
        method, url, error=new_e, _pool=self, _stacktrace=sys.exc_info()[2]
    )
  File "D:\Design & Source Code\Source Coding\Talented\venv\Lib\site-packages\urllib3\util\retry.py", line 519, in increment
    raise MaxRetryError(_pool, url, reason) from reason  # type: ignore[arg-type]
    ^^^^^^^^^^^^^^^^^^^^^^^^^^^^^^^^^^^^^^^^^^^^^^^^^^^
urllib3.exceptions.MaxRetryError: HTTPSConnectionPool(host='api-inference.huggingface.co', port=443): Max retries exceeded with url: /models/google/flan-t5-large (Caused by ProxyError('Unable to connect to proxy', NewConnectionError('<urllib3.connection.HTTPSConnection object at 0x00000254329A0CD0>: Failed to establish a new connection: [WinError 10061] No connection could be made because the target machine actively refused it')))

During handling of the above exception, another exception occurred:

Traceback (most recent call last):
  File "D:\Design & Source Code\Source Coding\Talented\quiz_finder\huggingface_utils.py", line 73, in generate_quiz_from_huggingface
    response = requests.post(API_URL, headers=headers, json=payload, timeout=45)
  File "D:\Design & Source Code\Source Coding\Talented\venv\Lib\site-packages\requests\api.py", line 115, in post
    return request("post", url, data=data, json=json, **kwargs)
  File "D:\Design & Source Code\Source Coding\Talented\venv\Lib\site-packages\requests\api.py", line 59, in request
    return session.request(method=method, url=url, **kwargs)
           ~~~~~~~~~~~~~~~^^^^^^^^^^^^^^^^^^^^^^^^^^^^^^^^^^
  File "D:\Design & Source Code\Source Coding\Talented\venv\Lib\site-packages\requests\sessions.py", line 589, in request
    resp = self.send(prep, **send_kwargs)
  File "D:\Design & Source Code\Source Coding\Talented\venv\Lib\site-packages\requests\sessions.py", line 703, in send
    r = adapter.send(request, **kwargs)
  File "D:\Design & Source Code\Source Coding\Talented\venv\Lib\site-packages\requests\adapters.py", line 671, in send
    raise ProxyError(e, request=request)
requests.exceptions.ProxyError: HTTPSConnectionPool(host='api-inference.huggingface.co', port=443): Max retries exceeded with url: /models/google/flan-t5-large (Caused by ProxyError('Unable to connect to proxy', NewConnectionError('<urllib3.connection.HTTPSConnection object at 0x00000254329A0CD0>: Failed to establish a new connection: [WinError 10061] No connection could be made because the target machine actively refused it')))
ERROR 2025-09-04 18:18:50 huggingface_utils generate_quiz_from_huggingface Error connecting to Hugging Face API: 404 Client Error: Not Found for url: https://api-inference.huggingface.co/models/google/flan-t5-large
Traceback (most recent call last):
  File "D:\Design & Source Code\Source Coding\Talented\quiz_finder\huggingface_utils.py", line 74, in generate_quiz_from_huggingface
    response.raise_for_status()
    ~~~~~~~~~~~~~~~~~~~~~~~~~^^
  File "D:\Design & Source Code\Source Coding\Talented\venv\Lib\site-packages\requests\models.py", line 1026, in raise_for_status
    raise HTTPError(http_error_msg, response=self)
requests.exceptions.HTTPError: 404 Client Error: Not Found for url: https://api-inference.huggingface.co/models/google/flan-t5-large
ERROR 2025-09-04 18:19:46 huggingface_utils generate_quiz_from_huggingface Error connecting to Hugging Face API: 404 Client Error: Not Found for url: https://api-inference.huggingface.co/models/google/flan-t5-large
Traceback (most recent call last):
  File "D:\Design & Source Code\Source Coding\Talented\quiz_finder\huggingface_utils.py", line 69, in generate_quiz_from_huggingface
    response.raise_for_status()
    ~~~~~~~~~~~~~~~~~~~~~~~~~^^
  File "D:\Design & Source Code\Source Coding\Talented\venv\Lib\site-packages\requests\models.py", line 1026, in raise_for_status
    raise HTTPError(http_error_msg, response=self)
requests.exceptions.HTTPError: 404 Client Error: Not Found for url: https://api-inference.huggingface.co/models/google/flan-t5-large
ERROR 2025-09-04 18:38:24 huggingface_utils generate_quiz_from_huggingface Error connecting to Hugging Face API: 404 Client Error: Not Found for url: https://api-inference.huggingface.co/models/google/flan-t5-large
Traceback (most recent call last):
  File "D:\Design & Source Code\Source Coding\Talented\quiz_finder\huggingface_utils.py", line 88, in generate_quiz_from_huggingface
    response.raise_for_status()
    ~~~~~~~~~~~~~~~~~~~~~~~~~^^
  File "D:\Design & Source Code\Source Coding\Talented\venv\Lib\site-packages\requests\models.py", line 1026, in raise_for_status
    raise HTTPError(http_error_msg, response=self)
requests.exceptions.HTTPError: 404 Client Error: Not Found for url: https://api-inference.huggingface.co/models/google/flan-t5-large
WARNING 2025-09-04 18:39:01 huggingface_utils generate_quiz_from_huggingface Connection failed for model https://api-inference.huggingface.co/models/google/flan-t5-large: 404 Client Error: Not Found for url: https://api-inference.huggingface.co/models/google/flan-t5-large
WARNING 2025-09-04 18:39:01 huggingface_utils generate_quiz_from_huggingface Connection failed for model https://api-inference.huggingface.co/models/google/flan-t5-base: 404 Client Error: Not Found for url: https://api-inference.huggingface.co/models/google/flan-t5-base
INFO 2025-09-04 18:39:01 huggingface_utils generate_quiz_from_huggingface Falling back to mock quiz data.
WARNING 2025-09-04 18:39:08 huggingface_utils generate_quiz_from_huggingface Connection failed for model https://api-inference.huggingface.co/models/google/flan-t5-large: 404 Client Error: Not Found for url: https://api-inference.huggingface.co/models/google/flan-t5-large
WARNING 2025-09-04 18:39:09 huggingface_utils generate_quiz_from_huggingface Connection failed for model https://api-inference.huggingface.co/models/google/flan-t5-base: 404 Client Error: Not Found for url: https://api-inference.huggingface.co/models/google/flan-t5-base
INFO 2025-09-04 18:39:09 huggingface_utils generate_quiz_from_huggingface Falling back to mock quiz data.
WARNING 2025-09-04 18:39:28 huggingface_utils generate_quiz_from_huggingface Connection failed for model https://api-inference.huggingface.co/models/google/flan-t5-large: 404 Client Error: Not Found for url: https://api-inference.huggingface.co/models/google/flan-t5-large
WARNING 2025-09-04 18:39:29 huggingface_utils generate_quiz_from_huggingface Connection failed for model https://api-inference.huggingface.co/models/google/flan-t5-base: 404 Client Error: Not Found for url: https://api-inference.huggingface.co/models/google/flan-t5-base
INFO 2025-09-04 18:39:29 huggingface_utils generate_quiz_from_huggingface Falling back to mock quiz data.
WARNING 2025-09-04 18:42:00 huggingface_utils generate_quiz_from_huggingface Connection failed for model https://api-inference.huggingface.co/models/google/flan-t5-large: 404 Client Error: Not Found for url: https://api-inference.huggingface.co/models/google/flan-t5-large
WARNING 2025-09-04 18:42:00 huggingface_utils generate_quiz_from_huggingface Connection failed for model https://api-inference.huggingface.co/models/google/flan-t5-base: 404 Client Error: Not Found for url: https://api-inference.huggingface.co/models/google/flan-t5-base
WARNING 2025-09-04 18:42:01 huggingface_utils generate_quiz_from_huggingface Connection failed for model https://api-inference.huggingface.co/models/HuggingFaceH4/zephyr-7b-alpha: 404 Client Error: Not Found for url: https://api-inference.huggingface.co/models/HuggingFaceH4/zephyr-7b-alpha
WARNING 2025-09-04 18:42:01 huggingface_utils generate_quiz_from_huggingface Connection failed for model https://api-inference.huggingface.co/models/meta-llama/Meta-Llama-3-8B-Instructhttps://api-inference.huggingface.co/models/meta-llama/Meta-Llama-3-8B-Instructhttps://api-inference.huggingface.co/models/HuggingFaceH4/zephyr-7b-alphahttps://api-inference.huggingface.co/models/google/flan-t5-basehttps://api-inference.huggingface.co/models/mistralai/Mixtral-8x7B-Instruct-v0.1https://api-inference.huggingface.co/models/google/flan-t5-largehttps://huggingface.co/meta-llama/Meta-Llama-3-8B-Instructhttps://api-inference.huggingface.co/models/mistralai/Mixtral-8x7B-Instruct-v0.1: 404 Client Error: Not Found for url: https://api-inference.huggingface.co/models/meta-llama/Meta-Llama-3-8B-Instructhttps://api-inference.huggingface.co/models/meta-llama/Meta-Llama-3-8B-Instructhttps://api-inference.huggingface.co/models/HuggingFaceH4/zephyr-7b-alphahttps://api-inference.huggingface.co/models/google/flan-t5-basehttps://api-inference.huggingface.co/models/mistralai/Mixtral-8x7B-Instruct-v0.1https://api-inference.huggingface.co/models/google/flan-t5-largehttps://huggingface.co/meta-llama/Meta-Llama-3-8B-Instructhttps://api-inference.huggingface.co/models/mistralai/Mixtral-8x7B-Instruct-v0.1
INFO 2025-09-04 18:42:01 huggingface_utils generate_quiz_from_huggingface Falling back to mock quiz data.
WARNING 2025-09-04 18:42:28 huggingface_utils generate_quiz_from_huggingface Connection failed for model https://api-inference.huggingface.co/models/google/flan-t5-large: 404 Client Error: Not Found for url: https://api-inference.huggingface.co/models/google/flan-t5-large
WARNING 2025-09-04 18:42:29 huggingface_utils generate_quiz_from_huggingface Connection failed for model https://api-inference.huggingface.co/models/google/flan-t5-base: 404 Client Error: Not Found for url: https://api-inference.huggingface.co/models/google/flan-t5-base
WARNING 2025-09-04 18:42:30 huggingface_utils generate_quiz_from_huggingface Connection failed for model https://api-inference.huggingface.co/models/HuggingFaceH4/zephyr-7b-alpha: 404 Client Error: Not Found for url: https://api-inference.huggingface.co/models/HuggingFaceH4/zephyr-7b-alpha
WARNING 2025-09-04 18:42:30 huggingface_utils generate_quiz_from_huggingface Connection failed for model https://api-inference.huggingface.co/models/meta-llama/Meta-Llama-3-8B-Instructhttps://api-inference.huggingface.co/models/meta-llama/Meta-Llama-3-8B-Instructhttps://api-inference.huggingface.co/models/HuggingFaceH4/zephyr-7b-alphahttps://api-inference.huggingface.co/models/google/flan-t5-basehttps://api-inference.huggingface.co/models/mistralai/Mixtral-8x7B-Instruct-v0.1https://api-inference.huggingface.co/models/google/flan-t5-largehttps://huggingface.co/meta-llama/Meta-Llama-3-8B-Instructhttps://api-inference.huggingface.co/models/mistralai/Mixtral-8x7B-Instruct-v0.1: 404 Client Error: Not Found for url: https://api-inference.huggingface.co/models/meta-llama/Meta-Llama-3-8B-Instructhttps://api-inference.huggingface.co/models/meta-llama/Meta-Llama-3-8B-Instructhttps://api-inference.huggingface.co/models/HuggingFaceH4/zephyr-7b-alphahttps://api-inference.huggingface.co/models/google/flan-t5-basehttps://api-inference.huggingface.co/models/mistralai/Mixtral-8x7B-Instruct-v0.1https://api-inference.huggingface.co/models/google/flan-t5-largehttps://huggingface.co/meta-llama/Meta-Llama-3-8B-Instructhttps://api-inference.huggingface.co/models/mistralai/Mixtral-8x7B-Instruct-v0.1
INFO 2025-09-04 18:42:30 huggingface_utils generate_quiz_from_huggingface Falling back to mock quiz data.
WARNING 2025-09-04 18:46:42 huggingface_utils generate_quiz_from_huggingface Connection failed for model https://api-inference.huggingface.co/models/mistralai/Mixtral-8x7B-Instruct-v0.1: 404 Client Error: Not Found for url: https://api-inference.huggingface.co/models/mistralai/Mixtral-8x7B-Instruct-v0.1
WARNING 2025-09-04 18:46:43 huggingface_utils generate_quiz_from_huggingface Connection failed for model https://api-inference.huggingface.co/models/meta-llama/Meta-Llama-3-8B-Instruct: 404 Client Error: Not Found for url: https://api-inference.huggingface.co/models/meta-llama/Meta-Llama-3-8B-Instruct
INFO 2025-09-04 18:46:43 huggingface_utils generate_quiz_from_huggingface Falling back to mock quiz data.
WARNING 2025-09-04 18:54:59 huggingface_utils generate_quiz_from_huggingface Connection failed for model https://api-inference.huggingface.co/models/mistralai/Mixtral-8x7B-Instruct-v0.1: 404 Client Error: Not Found for url: https://api-inference.huggingface.co/models/mistralai/Mixtral-8x7B-Instruct-v0.1
WARNING 2025-09-04 18:55:00 huggingface_utils generate_quiz_from_huggingface Connection failed for model https://api-inference.huggingface.co/models/meta-llama/Meta-Llama-3-8B-Instruct: 404 Client Error: Not Found for url: https://api-inference.huggingface.co/models/meta-llama/Meta-Llama-3-8B-Instruct
INFO 2025-09-04 18:55:00 huggingface_utils generate_quiz_from_huggingface Falling back to mock quiz data.
WARNING 2025-09-04 18:59:06 huggingface_utils generate_quiz_from_huggingface Hugging Face API Token not found. Using mock quiz.
WARNING 2025-09-04 18:59:22 huggingface_utils generate_quiz_from_huggingface Hugging Face API Token not found. Using mock quiz.
WARNING 2025-09-04 19:00:38 huggingface_utils generate_quiz_from_huggingface Hugging Face API Token not found. Using mock quiz.
WARNING 2025-09-04 19:01:42 huggingface_utils generate_quiz_from_huggingface Connection failed for model https://api-inference.huggingface.co/models/mistralai/Mixtral-8x7B-Instruct-v0.1: 404 Client Error: Not Found for url: https://api-inference.huggingface.co/models/mistralai/Mixtral-8x7B-Instruct-v0.1
WARNING 2025-09-04 19:01:43 huggingface_utils generate_quiz_from_huggingface Connection failed for model https://api-inference.huggingface.co/models/meta-llama/Meta-Llama-3-8B-Instruct: 404 Client Error: Not Found for url: https://api-inference.huggingface.co/models/meta-llama/Meta-Llama-3-8B-Instruct
INFO 2025-09-04 19:01:43 huggingface_utils generate_quiz_from_huggingface Falling back to mock quiz data.
WARNING 2025-09-04 19:07:39 huggingface_utils generate_quiz_from_huggingface Connection failed for model https://api-inference.huggingface.co/models/mistralai/Mixtral-8x7B-Instruct-v0.1: 404 Client Error: Not Found for url: https://api-inference.huggingface.co/models/mistralai/Mixtral-8x7B-Instruct-v0.1
WARNING 2025-09-04 19:07:40 huggingface_utils generate_quiz_from_huggingface Connection failed for model https://api-inference.huggingface.co/models/meta-llama/Meta-Llama-3-8B-Instruct: 404 Client Error: Not Found for url: https://api-inference.huggingface.co/models/meta-llama/Meta-Llama-3-8B-Instruct
INFO 2025-09-04 19:07:40 huggingface_utils generate_quiz_from_huggingface Falling back to mock quiz data.
WARNING 2025-09-04 19:08:03 huggingface_utils generate_quiz_from_huggingface Connection failed for model https://api-inference.huggingface.co/models/mistralai/Mixtral-8x7B-Instruct-v0.1: 404 Client Error: Not Found for url: https://api-inference.huggingface.co/models/mistralai/Mixtral-8x7B-Instruct-v0.1
WARNING 2025-09-04 19:08:04 huggingface_utils generate_quiz_from_huggingface Connection failed for model https://api-inference.huggingface.co/models/meta-llama/Meta-Llama-3-8B-Instruct: 404 Client Error: Not Found for url: https://api-inference.huggingface.co/models/meta-llama/Meta-Llama-3-8B-Instruct
INFO 2025-09-04 19:08:04 huggingface_utils generate_quiz_from_huggingface Falling back to mock quiz data.
WARNING 2025-09-04 20:04:43 huggingface_utils generate_quiz_from_huggingface Connection failed for model https://api-inference.huggingface.co/models/mistralai/Mixtral-8x7B-Instruct-v0.1: HTTPSConnectionPool(host='api-inference.huggingface.co', port=443): Read timed out. (read timeout=45)
WARNING 2025-09-04 20:04:44 huggingface_utils generate_quiz_from_huggingface Connection failed for model https://api-inference.huggingface.co/models/mistralai/Mixtral-8x7B-Instruct-v0.1: HTTPSConnectionPool(host='api-inference.huggingface.co', port=443): Read timed out. (read timeout=45)
WARNING 2025-09-04 20:05:29 huggingface_utils generate_quiz_from_huggingface Connection failed for model https://api-inference.huggingface.co/models/meta-llama/Meta-Llama-3-8B-Instruct: HTTPSConnectionPool(host='api-inference.huggingface.co', port=443): Read timed out. (read timeout=45)
INFO 2025-09-04 20:05:29 huggingface_utils generate_quiz_from_huggingface Falling back to mock quiz data.
WARNING 2025-09-04 20:05:30 huggingface_utils generate_quiz_from_huggingface Connection failed for model https://api-inference.huggingface.co/models/meta-llama/Meta-Llama-3-8B-Instruct: HTTPSConnectionPool(host='api-inference.huggingface.co', port=443): Read timed out. (read timeout=45)
INFO 2025-09-04 20:05:30 huggingface_utils generate_quiz_from_huggingface Falling back to mock quiz data.
WARNING 2025-09-04 20:07:53 huggingface_utils generate_quiz_from_huggingface Connection failed for model https://api-inference.huggingface.co/models/mistralai/Mixtral-8x7B-Instruct-v0.1: HTTPSConnectionPool(host='api-inference.huggingface.co', port=443): Read timed out. (read timeout=45)
WARNING 2025-09-04 20:08:39 huggingface_utils generate_quiz_from_huggingface Connection failed for model https://api-inference.huggingface.co/models/meta-llama/Meta-Llama-3-8B-Instruct: HTTPSConnectionPool(host='api-inference.huggingface.co', port=443): Read timed out. (read timeout=45)
INFO 2025-09-04 20:08:39 huggingface_utils generate_quiz_from_huggingface Falling back to mock quiz data.
WARNING 2025-09-04 20:09:23 huggingface_utils generate_quiz_from_huggingface Connection failed for model https://api-inference.huggingface.co/models/mistralai/Mixtral-8x7B-Instruct-v0.1: HTTPSConnectionPool(host='api-inference.huggingface.co', port=443): Read timed out. (read timeout=45)
WARNING 2025-09-04 20:10:08 huggingface_utils generate_quiz_from_huggingface Connection failed for model https://api-inference.huggingface.co/models/meta-llama/Meta-Llama-3-8B-Instruct: HTTPSConnectionPool(host='api-inference.huggingface.co', port=443): Read timed out. (read timeout=45)
INFO 2025-09-04 20:10:08 huggingface_utils generate_quiz_from_huggingface Falling back to mock quiz data.
WARNING 2025-09-04 20:10:36 huggingface_utils generate_quiz_from_huggingface Connection failed for model https://api-inference.huggingface.co/models/mistralai/Mixtral-8x7B-Instruct-v0.1: HTTPSConnectionPool(host='api-inference.huggingface.co', port=443): Read timed out. (read timeout=45)
WARNING 2025-09-04 20:11:22 huggingface_utils generate_quiz_from_huggingface Connection failed for model https://api-inference.huggingface.co/models/meta-llama/Meta-Llama-3-8B-Instruct: HTTPSConnectionPool(host='api-inference.huggingface.co', port=443): Read timed out. (read timeout=45)
INFO 2025-09-04 20:11:22 huggingface_utils generate_quiz_from_huggingface Falling back to mock quiz data.
WARNING 2025-09-04 20:14:21 huggingface_utils generate_quiz_from_huggingface Connection failed for model https://api-inference.huggingface.co/models/mistralai/Mixtral-8x7B-Instruct-v0.1: HTTPSConnectionPool(host='api-inference.huggingface.co', port=443): Read timed out. (read timeout=45)
WARNING 2025-09-04 20:15:07 huggingface_utils generate_quiz_from_huggingface Connection failed for model https://api-inference.huggingface.co/models/meta-llama/Meta-Llama-3-8B-Instruct: HTTPSConnectionPool(host='api-inference.huggingface.co', port=443): Read timed out. (read timeout=45)
INFO 2025-09-04 20:15:07 huggingface_utils generate_quiz_from_huggingface Falling back to mock quiz data.
WARNING 2025-09-04 20:19:19 huggingface_utils generate_quiz_from_huggingface Connection failed for model https://api-inference.huggingface.co/models/mistralai/Mixtral-8x7B-Instruct-v0.1: HTTPSConnectionPool(host='api-inference.huggingface.co', port=443): Read timed out. (read timeout=45)
WARNING 2025-09-04 20:20:05 huggingface_utils generate_quiz_from_huggingface Connection failed for model https://api-inference.huggingface.co/models/meta-llama/Meta-Llama-3-8B-Instruct: HTTPSConnectionPool(host='api-inference.huggingface.co', port=443): Read timed out. (read timeout=45)
INFO 2025-09-04 20:20:05 huggingface_utils generate_quiz_from_huggingface Falling back to mock quiz data.
WARNING 2025-09-04 20:24:28 huggingface_utils generate_quiz_from_huggingface Connection failed for model https://api-inference.huggingface.co/models/mistralai/Mixtral-8x7B-Instruct-v0.1: HTTPSConnectionPool(host='api-inference.huggingface.co', port=443): Read timed out. (read timeout=45)
WARNING 2025-09-04 20:25:13 huggingface_utils generate_quiz_from_huggingface Connection failed for model https://api-inference.huggingface.co/models/meta-llama/Meta-Llama-3-8B-Instruct: HTTPSConnectionPool(host='api-inference.huggingface.co', port=443): Read timed out. (read timeout=45)
INFO 2025-09-04 20:25:13 huggingface_utils generate_quiz_from_huggingface Falling back to mock quiz data.
WARNING 2025-09-04 20:35:26 huggingface_utils generate_quiz_from_huggingface Connection failed for model https://api-inference.huggingface.co/models/mistralai/Mixtral-8x7B-Instruct-v0.1: HTTPSConnectionPool(host='api-inference.huggingface.co', port=443): Read timed out. (read timeout=45)
WARNING 2025-09-04 20:36:12 huggingface_utils generate_quiz_from_huggingface Connection failed for model https://api-inference.huggingface.co/models/meta-llama/Meta-Llama-3-8B-Instruct: HTTPSConnectionPool(host='api-inference.huggingface.co', port=443): Read timed out. (read timeout=45)
INFO 2025-09-04 20:36:12 huggingface_utils generate_quiz_from_huggingface Falling back to mock quiz data.
WARNING 2025-09-04 21:40:23 huggingface_utils generate_quiz_from_huggingface Connection failed for model https://api-inference.huggingface.co/models/mistralai/Mixtral-8x7B-Instruct-v0.1: HTTPSConnectionPool(host='api-inference.huggingface.co', port=443): Read timed out. (read timeout=45)
WARNING 2025-09-04 21:41:09 huggingface_utils generate_quiz_from_huggingface Connection failed for model https://api-inference.huggingface.co/models/meta-llama/Meta-Llama-3-8B-Instruct: HTTPSConnectionPool(host='api-inference.huggingface.co', port=443): Read timed out. (read timeout=45)
INFO 2025-09-04 21:41:09 huggingface_utils generate_quiz_from_huggingface Falling back to mock quiz data.
WARNING 2025-09-04 22:47:33 huggingface_utils generate_quiz_from_huggingface Connection failed for model https://api-inference.huggingface.co/models/mistralai/Mixtral-8x7B-Instruct-v0.1: HTTPSConnectionPool(host='api-inference.huggingface.co', port=443): Read timed out. (read timeout=45)
WARNING 2025-09-04 22:48:21 huggingface_utils generate_quiz_from_huggingface Connection failed for model https://api-inference.huggingface.co/models/meta-llama/Meta-Llama-3-8B-Instruct: HTTPSConnectionPool(host='api-inference.huggingface.co', port=443): Read timed out. (read timeout=45)
INFO 2025-09-04 22:48:21 huggingface_utils generate_quiz_from_huggingface Falling back to mock quiz data.
WARNING 2025-09-04 23:05:08 file_download _download_to_tmp_and_move Xet Storage is enabled for this repo, but the 'hf_xet' package is not installed. Falling back to regular HTTP download. For better performance, install the package with: `pip install huggingface_hub[hf_xet]` or `pip install hf_xet`
