ERROR 2025-09-04 18:08:17 huggingface_utils generate_quiz_from_huggingface Error connecting to Hugging Face API: HTTPSConnectionPool(host='api-inference.huggingface.co', port=443): Max retries exceeded with url: /models/google/flan-t5-large (Caused by ProxyError('Unable to connect to proxy', NewConnectionError('<urllib3.connection.HTTPSConnection object at 0x000001CBB19F02F0>: Failed to establish a new connection: [WinError 10061] No connection could be made because the target machine actively refused it')))
Traceback (most recent call last):
  File "D:\Design & Source Code\Source Coding\Talented\venv\Lib\site-packages\urllib3\connection.py", line 198, in _new_conn
    sock = connection.create_connection(
        (self._dns_host, self.port),
    ...<2 lines>...
        socket_options=self.socket_options,
    )
  File "D:\Design & Source Code\Source Coding\Talented\venv\Lib\site-packages\urllib3\util\connection.py", line 85, in create_connection
    raise err
  File "D:\Design & Source Code\Source Coding\Talented\venv\Lib\site-packages\urllib3\util\connection.py", line 73, in create_connection
    sock.connect(sa)
    ~~~~~~~~~~~~^^^^
ConnectionRefusedError: [WinError 10061] No connection could be made because the target machine actively refused it

The above exception was the direct cause of the following exception:

Traceback (most recent call last):
  File "D:\Design & Source Code\Source Coding\Talented\venv\Lib\site-packages\urllib3\connectionpool.py", line 773, in urlopen
    self._prepare_proxy(conn)
    ~~~~~~~~~~~~~~~~~~~^^^^^^
  File "D:\Design & Source Code\Source Coding\Talented\venv\Lib\site-packages\urllib3\connectionpool.py", line 1042, in _prepare_proxy
    conn.connect()
    ~~~~~~~~~~~~^^
  File "D:\Design & Source Code\Source Coding\Talented\venv\Lib\site-packages\urllib3\connection.py", line 753, in connect
    self.sock = sock = self._new_conn()
                       ~~~~~~~~~~~~~~^^
  File "D:\Design & Source Code\Source Coding\Talented\venv\Lib\site-packages\urllib3\connection.py", line 213, in _new_conn
    raise NewConnectionError(
        self, f"Failed to establish a new connection: {e}"
    ) from e
urllib3.exceptions.NewConnectionError: <urllib3.connection.HTTPSConnection object at 0x000001CBB19F02F0>: Failed to establish a new connection: [WinError 10061] No connection could be made because the target machine actively refused it

The above exception was the direct cause of the following exception:

urllib3.exceptions.ProxyError: ('Unable to connect to proxy', NewConnectionError('<urllib3.connection.HTTPSConnection object at 0x000001CBB19F02F0>: Failed to establish a new connection: [WinError 10061] No connection could be made because the target machine actively refused it'))

The above exception was the direct cause of the following exception:

Traceback (most recent call last):
  File "D:\Design & Source Code\Source Coding\Talented\venv\Lib\site-packages\requests\adapters.py", line 644, in send
    resp = conn.urlopen(
        method=request.method,
    ...<9 lines>...
        chunked=chunked,
    )
  File "D:\Design & Source Code\Source Coding\Talented\venv\Lib\site-packages\urllib3\connectionpool.py", line 841, in urlopen
    retries = retries.increment(
        method, url, error=new_e, _pool=self, _stacktrace=sys.exc_info()[2]
    )
  File "D:\Design & Source Code\Source Coding\Talented\venv\Lib\site-packages\urllib3\util\retry.py", line 519, in increment
    raise MaxRetryError(_pool, url, reason) from reason  # type: ignore[arg-type]
    ^^^^^^^^^^^^^^^^^^^^^^^^^^^^^^^^^^^^^^^^^^^^^^^^^^^
urllib3.exceptions.MaxRetryError: HTTPSConnectionPool(host='api-inference.huggingface.co', port=443): Max retries exceeded with url: /models/google/flan-t5-large (Caused by ProxyError('Unable to connect to proxy', NewConnectionError('<urllib3.connection.HTTPSConnection object at 0x000001CBB19F02F0>: Failed to establish a new connection: [WinError 10061] No connection could be made because the target machine actively refused it')))

During handling of the above exception, another exception occurred:

Traceback (most recent call last):
  File "D:\Design & Source Code\Source Coding\Talented\quiz_finder\huggingface_utils.py", line 74, in generate_quiz_from_huggingface
    response = requests.post(API_URL, headers=headers, json=payload, timeout=45)
  File "D:\Design & Source Code\Source Coding\Talented\venv\Lib\site-packages\requests\api.py", line 115, in post
    return request("post", url, data=data, json=json, **kwargs)
  File "D:\Design & Source Code\Source Coding\Talented\venv\Lib\site-packages\requests\api.py", line 59, in request
    return session.request(method=method, url=url, **kwargs)
           ~~~~~~~~~~~~~~~^^^^^^^^^^^^^^^^^^^^^^^^^^^^^^^^^^
  File "D:\Design & Source Code\Source Coding\Talented\venv\Lib\site-packages\requests\sessions.py", line 589, in request
    resp = self.send(prep, **send_kwargs)
  File "D:\Design & Source Code\Source Coding\Talented\venv\Lib\site-packages\requests\sessions.py", line 703, in send
    r = adapter.send(request, **kwargs)
  File "D:\Design & Source Code\Source Coding\Talented\venv\Lib\site-packages\requests\adapters.py", line 671, in send
    raise ProxyError(e, request=request)
requests.exceptions.ProxyError: HTTPSConnectionPool(host='api-inference.huggingface.co', port=443): Max retries exceeded with url: /models/google/flan-t5-large (Caused by ProxyError('Unable to connect to proxy', NewConnectionError('<urllib3.connection.HTTPSConnection object at 0x000001CBB19F02F0>: Failed to establish a new connection: [WinError 10061] No connection could be made because the target machine actively refused it')))
ERROR 2025-09-04 18:15:09 huggingface_utils generate_quiz_from_huggingface Error connecting to Hugging Face API: HTTPSConnectionPool(host='api-inference.huggingface.co', port=443): Max retries exceeded with url: /models/google/flan-t5-large (Caused by ProxyError('Unable to connect to proxy', NewConnectionError('<urllib3.connection.HTTPSConnection object at 0x000002543280C050>: Failed to establish a new connection: [WinError 10061] No connection could be made because the target machine actively refused it')))
Traceback (most recent call last):
  File "D:\Design & Source Code\Source Coding\Talented\venv\Lib\site-packages\urllib3\connection.py", line 198, in _new_conn
    sock = connection.create_connection(
        (self._dns_host, self.port),
    ...<2 lines>...
        socket_options=self.socket_options,
    )
  File "D:\Design & Source Code\Source Coding\Talented\venv\Lib\site-packages\urllib3\util\connection.py", line 85, in create_connection
    raise err
  File "D:\Design & Source Code\Source Coding\Talented\venv\Lib\site-packages\urllib3\util\connection.py", line 73, in create_connection
    sock.connect(sa)
    ~~~~~~~~~~~~^^^^
ConnectionRefusedError: [WinError 10061] No connection could be made because the target machine actively refused it

The above exception was the direct cause of the following exception:

Traceback (most recent call last):
  File "D:\Design & Source Code\Source Coding\Talented\venv\Lib\site-packages\urllib3\connectionpool.py", line 773, in urlopen
    self._prepare_proxy(conn)
    ~~~~~~~~~~~~~~~~~~~^^^^^^
  File "D:\Design & Source Code\Source Coding\Talented\venv\Lib\site-packages\urllib3\connectionpool.py", line 1042, in _prepare_proxy
    conn.connect()
    ~~~~~~~~~~~~^^
  File "D:\Design & Source Code\Source Coding\Talented\venv\Lib\site-packages\urllib3\connection.py", line 753, in connect
    self.sock = sock = self._new_conn()
                       ~~~~~~~~~~~~~~^^
  File "D:\Design & Source Code\Source Coding\Talented\venv\Lib\site-packages\urllib3\connection.py", line 213, in _new_conn
    raise NewConnectionError(
        self, f"Failed to establish a new connection: {e}"
    ) from e
urllib3.exceptions.NewConnectionError: <urllib3.connection.HTTPSConnection object at 0x000002543280C050>: Failed to establish a new connection: [WinError 10061] No connection could be made because the target machine actively refused it

The above exception was the direct cause of the following exception:

urllib3.exceptions.ProxyError: ('Unable to connect to proxy', NewConnectionError('<urllib3.connection.HTTPSConnection object at 0x000002543280C050>: Failed to establish a new connection: [WinError 10061] No connection could be made because the target machine actively refused it'))

The above exception was the direct cause of the following exception:

Traceback (most recent call last):
  File "D:\Design & Source Code\Source Coding\Talented\venv\Lib\site-packages\requests\adapters.py", line 644, in send
    resp = conn.urlopen(
        method=request.method,
    ...<9 lines>...
        chunked=chunked,
    )
  File "D:\Design & Source Code\Source Coding\Talented\venv\Lib\site-packages\urllib3\connectionpool.py", line 841, in urlopen
    retries = retries.increment(
        method, url, error=new_e, _pool=self, _stacktrace=sys.exc_info()[2]
    )
  File "D:\Design & Source Code\Source Coding\Talented\venv\Lib\site-packages\urllib3\util\retry.py", line 519, in increment
    raise MaxRetryError(_pool, url, reason) from reason  # type: ignore[arg-type]
    ^^^^^^^^^^^^^^^^^^^^^^^^^^^^^^^^^^^^^^^^^^^^^^^^^^^
urllib3.exceptions.MaxRetryError: HTTPSConnectionPool(host='api-inference.huggingface.co', port=443): Max retries exceeded with url: /models/google/flan-t5-large (Caused by ProxyError('Unable to connect to proxy', NewConnectionError('<urllib3.connection.HTTPSConnection object at 0x000002543280C050>: Failed to establish a new connection: [WinError 10061] No connection could be made because the target machine actively refused it')))

During handling of the above exception, another exception occurred:

Traceback (most recent call last):
  File "D:\Design & Source Code\Source Coding\Talented\quiz_finder\huggingface_utils.py", line 73, in generate_quiz_from_huggingface
    response = requests.post(API_URL, headers=headers, json=payload, timeout=45)
  File "D:\Design & Source Code\Source Coding\Talented\venv\Lib\site-packages\requests\api.py", line 115, in post
    return request("post", url, data=data, json=json, **kwargs)
  File "D:\Design & Source Code\Source Coding\Talented\venv\Lib\site-packages\requests\api.py", line 59, in request
    return session.request(method=method, url=url, **kwargs)
           ~~~~~~~~~~~~~~~^^^^^^^^^^^^^^^^^^^^^^^^^^^^^^^^^^
  File "D:\Design & Source Code\Source Coding\Talented\venv\Lib\site-packages\requests\sessions.py", line 589, in request
    resp = self.send(prep, **send_kwargs)
  File "D:\Design & Source Code\Source Coding\Talented\venv\Lib\site-packages\requests\sessions.py", line 703, in send
    r = adapter.send(request, **kwargs)
  File "D:\Design & Source Code\Source Coding\Talented\venv\Lib\site-packages\requests\adapters.py", line 671, in send
    raise ProxyError(e, request=request)
requests.exceptions.ProxyError: HTTPSConnectionPool(host='api-inference.huggingface.co', port=443): Max retries exceeded with url: /models/google/flan-t5-large (Caused by ProxyError('Unable to connect to proxy', NewConnectionError('<urllib3.connection.HTTPSConnection object at 0x000002543280C050>: Failed to establish a new connection: [WinError 10061] No connection could be made because the target machine actively refused it')))
ERROR 2025-09-04 18:16:15 huggingface_utils generate_quiz_from_huggingface Error connecting to Hugging Face API: HTTPSConnectionPool(host='api-inference.huggingface.co', port=443): Max retries exceeded with url: /models/google/flan-t5-large (Caused by ProxyError('Unable to connect to proxy', NewConnectionError('<urllib3.connection.HTTPSConnection object at 0x00000254329A0CD0>: Failed to establish a new connection: [WinError 10061] No connection could be made because the target machine actively refused it')))
Traceback (most recent call last):
  File "D:\Design & Source Code\Source Coding\Talented\venv\Lib\site-packages\urllib3\connection.py", line 198, in _new_conn
    sock = connection.create_connection(
        (self._dns_host, self.port),
    ...<2 lines>...
        socket_options=self.socket_options,
    )
  File "D:\Design & Source Code\Source Coding\Talented\venv\Lib\site-packages\urllib3\util\connection.py", line 85, in create_connection
    raise err
  File "D:\Design & Source Code\Source Coding\Talented\venv\Lib\site-packages\urllib3\util\connection.py", line 73, in create_connection
    sock.connect(sa)
    ~~~~~~~~~~~~^^^^
ConnectionRefusedError: [WinError 10061] No connection could be made because the target machine actively refused it

The above exception was the direct cause of the following exception:

Traceback (most recent call last):
  File "D:\Design & Source Code\Source Coding\Talented\venv\Lib\site-packages\urllib3\connectionpool.py", line 773, in urlopen
    self._prepare_proxy(conn)
    ~~~~~~~~~~~~~~~~~~~^^^^^^
  File "D:\Design & Source Code\Source Coding\Talented\venv\Lib\site-packages\urllib3\connectionpool.py", line 1042, in _prepare_proxy
    conn.connect()
    ~~~~~~~~~~~~^^
  File "D:\Design & Source Code\Source Coding\Talented\venv\Lib\site-packages\urllib3\connection.py", line 753, in connect
    self.sock = sock = self._new_conn()
                       ~~~~~~~~~~~~~~^^
  File "D:\Design & Source Code\Source Coding\Talented\venv\Lib\site-packages\urllib3\connection.py", line 213, in _new_conn
    raise NewConnectionError(
        self, f"Failed to establish a new connection: {e}"
    ) from e
urllib3.exceptions.NewConnectionError: <urllib3.connection.HTTPSConnection object at 0x00000254329A0CD0>: Failed to establish a new connection: [WinError 10061] No connection could be made because the target machine actively refused it

The above exception was the direct cause of the following exception:

urllib3.exceptions.ProxyError: ('Unable to connect to proxy', NewConnectionError('<urllib3.connection.HTTPSConnection object at 0x00000254329A0CD0>: Failed to establish a new connection: [WinError 10061] No connection could be made because the target machine actively refused it'))

The above exception was the direct cause of the following exception:

Traceback (most recent call last):
  File "D:\Design & Source Code\Source Coding\Talented\venv\Lib\site-packages\requests\adapters.py", line 644, in send
    resp = conn.urlopen(
        method=request.method,
    ...<9 lines>...
        chunked=chunked,
    )
  File "D:\Design & Source Code\Source Coding\Talented\venv\Lib\site-packages\urllib3\connectionpool.py", line 841, in urlopen
    retries = retries.increment(
        method, url, error=new_e, _pool=self, _stacktrace=sys.exc_info()[2]
    )
  File "D:\Design & Source Code\Source Coding\Talented\venv\Lib\site-packages\urllib3\util\retry.py", line 519, in increment
    raise MaxRetryError(_pool, url, reason) from reason  # type: ignore[arg-type]
    ^^^^^^^^^^^^^^^^^^^^^^^^^^^^^^^^^^^^^^^^^^^^^^^^^^^
urllib3.exceptions.MaxRetryError: HTTPSConnectionPool(host='api-inference.huggingface.co', port=443): Max retries exceeded with url: /models/google/flan-t5-large (Caused by ProxyError('Unable to connect to proxy', NewConnectionError('<urllib3.connection.HTTPSConnection object at 0x00000254329A0CD0>: Failed to establish a new connection: [WinError 10061] No connection could be made because the target machine actively refused it')))

During handling of the above exception, another exception occurred:

Traceback (most recent call last):
  File "D:\Design & Source Code\Source Coding\Talented\quiz_finder\huggingface_utils.py", line 73, in generate_quiz_from_huggingface
    response = requests.post(API_URL, headers=headers, json=payload, timeout=45)
  File "D:\Design & Source Code\Source Coding\Talented\venv\Lib\site-packages\requests\api.py", line 115, in post
    return request("post", url, data=data, json=json, **kwargs)
  File "D:\Design & Source Code\Source Coding\Talented\venv\Lib\site-packages\requests\api.py", line 59, in request
    return session.request(method=method, url=url, **kwargs)
           ~~~~~~~~~~~~~~~^^^^^^^^^^^^^^^^^^^^^^^^^^^^^^^^^^
  File "D:\Design & Source Code\Source Coding\Talented\venv\Lib\site-packages\requests\sessions.py", line 589, in request
    resp = self.send(prep, **send_kwargs)
  File "D:\Design & Source Code\Source Coding\Talented\venv\Lib\site-packages\requests\sessions.py", line 703, in send
    r = adapter.send(request, **kwargs)
  File "D:\Design & Source Code\Source Coding\Talented\venv\Lib\site-packages\requests\adapters.py", line 671, in send
    raise ProxyError(e, request=request)
requests.exceptions.ProxyError: HTTPSConnectionPool(host='api-inference.huggingface.co', port=443): Max retries exceeded with url: /models/google/flan-t5-large (Caused by ProxyError('Unable to connect to proxy', NewConnectionError('<urllib3.connection.HTTPSConnection object at 0x00000254329A0CD0>: Failed to establish a new connection: [WinError 10061] No connection could be made because the target machine actively refused it')))
ERROR 2025-09-04 18:18:50 huggingface_utils generate_quiz_from_huggingface Error connecting to Hugging Face API: 404 Client Error: Not Found for url: https://api-inference.huggingface.co/models/google/flan-t5-large
Traceback (most recent call last):
  File "D:\Design & Source Code\Source Coding\Talented\quiz_finder\huggingface_utils.py", line 74, in generate_quiz_from_huggingface
    response.raise_for_status()
    ~~~~~~~~~~~~~~~~~~~~~~~~~^^
  File "D:\Design & Source Code\Source Coding\Talented\venv\Lib\site-packages\requests\models.py", line 1026, in raise_for_status
    raise HTTPError(http_error_msg, response=self)
requests.exceptions.HTTPError: 404 Client Error: Not Found for url: https://api-inference.huggingface.co/models/google/flan-t5-large
ERROR 2025-09-04 18:19:46 huggingface_utils generate_quiz_from_huggingface Error connecting to Hugging Face API: 404 Client Error: Not Found for url: https://api-inference.huggingface.co/models/google/flan-t5-large
Traceback (most recent call last):
  File "D:\Design & Source Code\Source Coding\Talented\quiz_finder\huggingface_utils.py", line 69, in generate_quiz_from_huggingface
    response.raise_for_status()
    ~~~~~~~~~~~~~~~~~~~~~~~~~^^
  File "D:\Design & Source Code\Source Coding\Talented\venv\Lib\site-packages\requests\models.py", line 1026, in raise_for_status
    raise HTTPError(http_error_msg, response=self)
requests.exceptions.HTTPError: 404 Client Error: Not Found for url: https://api-inference.huggingface.co/models/google/flan-t5-large
ERROR 2025-09-04 18:38:24 huggingface_utils generate_quiz_from_huggingface Error connecting to Hugging Face API: 404 Client Error: Not Found for url: https://api-inference.huggingface.co/models/google/flan-t5-large
Traceback (most recent call last):
  File "D:\Design & Source Code\Source Coding\Talented\quiz_finder\huggingface_utils.py", line 88, in generate_quiz_from_huggingface
    response.raise_for_status()
    ~~~~~~~~~~~~~~~~~~~~~~~~~^^
  File "D:\Design & Source Code\Source Coding\Talented\venv\Lib\site-packages\requests\models.py", line 1026, in raise_for_status
    raise HTTPError(http_error_msg, response=self)
requests.exceptions.HTTPError: 404 Client Error: Not Found for url: https://api-inference.huggingface.co/models/google/flan-t5-large
