ERROR 2025-09-04 15:11:01 log log_response Internal Server Error: /
Traceback (most recent call last):
  File "D:\Design & Source Code\Source Coding\Talented\venv\Lib\site-packages\django\core\handlers\exception.py", line 55, in inner
    response = get_response(request)
  File "D:\Design & Source Code\Source Coding\Talented\venv\Lib\site-packages\django\core\handlers\base.py", line 220, in _get_response
    response = response.render()
  File "D:\Design & Source Code\Source Coding\Talented\venv\Lib\site-packages\django\template\response.py", line 114, in render
    self.content = self.rendered_content
                   ^^^^^^^^^^^^^^^^^^^^^
  File "D:\Design & Source Code\Source Coding\Talented\venv\Lib\site-packages\django\template\response.py", line 90, in rendered_content
    template = self.resolve_template(self.template_name)
  File "D:\Design & Source Code\Source Coding\Talented\venv\Lib\site-packages\django\template\response.py", line 72, in resolve_template
    return select_template(template, using=self.using)
  File "D:\Design & Source Code\Source Coding\Talented\venv\Lib\site-packages\django\template\loader.py", line 47, in select_template
    raise TemplateDoesNotExist(", ".join(template_name_list), chain=chain)
django.template.exceptions.TemplateDoesNotExist: quiz_finder/home.html
ERROR 2025-09-04 15:11:01 basehttp log_message "GET / HTTP/1.1" 500 85540
ERROR 2025-09-04 15:11:26 log log_response Internal Server Error: /
Traceback (most recent call last):
  File "D:\Design & Source Code\Source Coding\Talented\venv\Lib\site-packages\django\core\handlers\exception.py", line 55, in inner
    response = get_response(request)
  File "D:\Design & Source Code\Source Coding\Talented\venv\Lib\site-packages\django\core\handlers\base.py", line 220, in _get_response
    response = response.render()
  File "D:\Design & Source Code\Source Coding\Talented\venv\Lib\site-packages\django\template\response.py", line 114, in render
    self.content = self.rendered_content
                   ^^^^^^^^^^^^^^^^^^^^^
  File "D:\Design & Source Code\Source Coding\Talented\venv\Lib\site-packages\django\template\response.py", line 90, in rendered_content
    template = self.resolve_template(self.template_name)
  File "D:\Design & Source Code\Source Coding\Talented\venv\Lib\site-packages\django\template\response.py", line 72, in resolve_template
    return select_template(template, using=self.using)
  File "D:\Design & Source Code\Source Coding\Talented\venv\Lib\site-packages\django\template\loader.py", line 47, in select_template
    raise TemplateDoesNotExist(", ".join(template_name_list), chain=chain)
django.template.exceptions.TemplateDoesNotExist: quiz_finder/home.html
ERROR 2025-09-04 15:11:26 basehttp log_message "GET / HTTP/1.1" 500 85263
ERROR 2025-09-04 15:14:52 log log_response Internal Server Error: /api/generate-quiz/
ERROR 2025-09-04 15:14:52 basehttp log_message "POST /api/generate-quiz/ HTTP/1.1" 500 332
ERROR 2025-09-04 16:14:04 log log_response Internal Server Error: /api/generate-quiz/
ERROR 2025-09-04 16:14:04 basehttp log_message "POST /api/generate-quiz/ HTTP/1.1" 500 332
ERROR 2025-09-04 16:20:57 log log_response Internal Server Error: /api/generate-quiz/
ERROR 2025-09-04 16:20:57 basehttp log_message "POST /api/generate-quiz/ HTTP/1.1" 500 332
ERROR 2025-09-04 16:54:20 log log_response Internal Server Error: /api/generate-quiz/
ERROR 2025-09-04 16:54:20 basehttp log_message "POST /api/generate-quiz/ HTTP/1.1" 500 332
